<?xml version="1.0" encoding="utf-8"?>
<robot name="smcpomdpballoon" xmlns:xacro="http://ros.org/wiki/xacro">
  <link
    name="base_link">
    <inertial>
      <origin
        xyz="0 0 0"
        rpy="0 0 0" />
      <mass
        value="0.52" />
      <inertia
        ixx="1530000.25"
        ixy="0"
        ixz="0"
        iyy="1530000.25"
        iyz="0"
        izz="2075000.5" />
    </inertial>
    <visual>
      <origin
        xyz="0 0 0"
        rpy="0 0 0" />
      <geometry>
        <mesh
          filename="file://$(find smcpomdpballoon)/models/base_link.STL" scale="0.12 0.12 0.12"/>
      </geometry>
      <material
        name="">
        <color
          rgba="0.752941176470588 0.752941176470588 0.752941176470588 1" />
      </material>
    </visual>
    <collision>
      <origin
        xyz="0 0 0.1"
        rpy="0 0 0" />
      <geometry>
         <box size = "0.25 0.25 0.2" />
      </geometry>
    </collision>
  </link>
  
  <link
    name="propright">
    <inertial>
      <origin
        xyz="0 0 0"
        rpy="0 0 0" />
      <mass
        value="0.01" />
      <inertia
        ixx="0.00004"
        ixy="0"
        ixz="0"
        iyy="0.00004"
        iyz="0"
        izz="0.000025" />
    </inertial>
    <visual>
      <origin
        xyz="0 0 0"
        rpy="0 0 0" />
      <geometry>
        <mesh
          filename="file://$(find smcpomdpballoon)/models/propright.STL" scale="0.75 0.75 0.75"/>
      </geometry>
      <material
        name="">
        <color
          rgba="0.294117647058824 0.294117647058824 0.294117647058824 1" />
      </material>
    </visual>
    <collision>
      <origin
        xyz="0 0 0"
        rpy="0 0 0" />
      <geometry>
        <mesh
          filename="file://$(find smcpomdpballoon)/models/propright.STL" scale="0.75 0.75 0.75"/>
      </geometry>
    </collision>
  </link>
  <joint
    name="pbr"
    type="continuous">
    <origin
      xyz="0 0 0.165"
      rpy="0 0 0" />
    <parent
      link="base_link" />
    <child
      link="propright" />
    <axis
      xyz="0 0 -1" />
  </joint>

  <link
    name="propleft">
    <inertial>
      <origin
        xyz="0 0 0"
        rpy="0 0 0" />
      <mass
        value="0.01" />
      <inertia
        ixx="0.00004"
        ixy="0"
        ixz="0"
        iyy="0.00004"
        iyz="0"
        izz="0.000025" />
    </inertial>
    <visual>
      <origin
        xyz="0 0 0"
        rpy="0 0 0" />
      <geometry>
        <mesh
          filename="file://$(find smcpomdpballoon)/models/propleft.STL" scale="0.75 0.75 0.75"/>
      </geometry>
      <material
        name="">
        <color
          rgba="0.294117647058824 0.294117647058824 0.294117647058824 1" />
      </material>
    </visual>
    <collision>
      <origin
        xyz="0 0 0"
        rpy="0 0 0" />
      <geometry>
        <mesh
          filename="file://$(find smcpomdpballoon)/models/propleft.STL" scale="0.75 0.75 0.75"/>
      </geometry>
    </collision>
  </link>
  <joint
    name="pbl"
    type="continuous">
    <origin
      xyz="0 0 0.31"
      rpy="0 0 0" />
    <parent
      link="base_link" />
    <child
      link="propleft" />
    <axis
      xyz="0 0 -1" />
  </joint>

  <link
    name="propleftbase">
    <inertial>
      <origin
        xyz="0 0 0"
        rpy="0 0 0" />
      <mass
        value="0.01" />
      <inertia
        ixx="0.00004"
        ixy="0"
        ixz="0"
        iyy="0.00004"
        iyz="0"
        izz="0.000025" />
    </inertial>
    <visual>
      <origin
        xyz="0 0 0"
        rpy="0 0 0" />
      <geometry>
        <cylinder radius="0.0025" length="0.155" />
      </geometry>
      <material
        name="">
        <color
          rgba="0.294117647058824 0.294117647058824 0.294117647058824 1" />
      </material>
    </visual>
    <collision>
      <origin
        xyz="0 0 0"
        rpy="0 0 0" />
      <geometry>
        <cylinder radius="0.0025" length="0.155" />
      </geometry>
    </collision>
  </link>

  <joint
    name="plfbased"
    type="fixed">
    <origin
      xyz="0 0 0.2375"
      rpy="0 0 0" />
    <parent
      link="base_link" />
    <child
      link="propleftbase" />
    <axis
      xyz="0 0 -1" />
  </joint>

  <gazebo>
    <plugin name="gazebo_ros_state" filename="libgazebo_ros_p3d.so">
      <ros>
        <namespace>/droneposition</namespace>
      </ros>
      <update_rate>1000</update_rate> 
      <body_name>base_link</body_name> <!-- Link to track -->
      <frame_name>world</frame_name>
    </plugin>
  </gazebo>

  <gazebo>
  <plugin name="smcpomdpballoonplugin" filename="/home/vanchung/dev_ws/install/smcpomdpballoon/lib/smcpomdpballoon/libsmcpomdpballoonplugin.so">
      <updateRate>1000</updateRate> 
      <publishTf>true</publishTf>
    </plugin>
  </gazebo>

</robot>